Workbook

Sheet 1. Share_Price_Analysis
B1: Sheet 1: Share Price Analysis
B3: General Information | D3: Market Stats
B4: General Information | D4: Market Stats
B5: Analysis Company | C5: Vulcan Materials (VMC) | D5: Current Price | E5: ='[1]Sheet9_Financial Data'!C755 -> 295.98 | L5: =2/(50+1) -> 0.039215686
B6: Ticker | C6: VMC.N | D6: Market Cap | E6: 37,510,000,000
B7: Benchmark | C7: SPY500 | D7: 52W High | E7: =MAX('[1]Sheet9_Financial Data'!C503:C754) -> 330.37
B8: Sector Benchmark | C8: XLB | D8: 52W Low | E8: =MIN('[1]Sheet9_Financial Data'!C504:C755) -> 220.9
B9: End date | C9: ='[1]Sheet9_Financial Data'!B4 -> 44991 | D9: Average Daily Return | E9: =AVERAGE('[1]Sheet9_Financial Data'!F5:F755) -> 0.0007791693
B10: Start date | C10: ='[1]Sheet9_Financial Data'!B755 -> 46085 | D10: Risk Free Rate | E10: 0.04
B11: Trading days | C11: 252 | D11: Alpha | E11: =2/(200+1) -> 0.0099502488
B13: Metrics | C13: VMC | D13: SPY | E13: XLB
B14: Annualized Return | C14: {=GEOMEAN(1+'[1]Sheet9_Financial Data'!F$5:F$755)^$C$11-1} -> 0.18207784 | D14: {=GEOMEAN(1+'[1]Sheet9_Financial Data'!G$5:G$755)^$C$11-1} -> 0.19344804 | E14: {=GEOMEAN(1+'[1]Sheet9_Financial Data'!H$5:H$755)^$C$11-1} -> 0.077063972
B15: Annualized Volatility | C15: =_xlfn.STDEV.S('[1]Sheet9_Financial Data'!F5:F755)*SQRT($C$11) -> 0.24100121 | D15: =_xlfn.STDEV.S('[1]Sheet9_Financial Data'!G5:G755)*SQRT($C$11) -> 0.15160814 | E15: =_xlfn.STDEV.S('[1]Sheet9_Financial Data'!H5:H755)*SQRT($C$11) -> 0.1707121
B16: Total Return | C16: ='[1]Sheet9_Financial Data'!C755/'[1]Sheet9_Financial Data'!C4 - 1 -> 0.64625396 | D16: ='[1]Sheet9_Financial Data'!D755/'[1]Sheet9_Financial Data'!D4 - 1 -> 0.69389572 | E16: ='[1]Sheet9_Financial Data'!E755/'[1]Sheet9_Financial Data'!E4 - 1 -> 0.24762706
B17: Beta vs SPY | C17: =SLOPE('[1]Sheet9_Financial Data'!$F$5:$F$755,'[1]Sheet9_Financial Data'!G5:G755) -> 0.82769326
B18: Beta vs XLB | C18: =SLOPE('[1]Sheet9_Financial Data'!$F$5:$F$755,'[1]Sheet9_Financial Data'!H5:H755) -> 0.79887867
B19: Sharpe Ratio | C19: =(C14-E10)/C15 -> 0.58953163
B20: Max Drawdown | C20: =MIN('[1]Sheet9_Financial Data'!T4:T755) -> -0.24429544
B63: Date | C63: VMC Adj Close | D63: SPY Adj Close | E63: XLB Adj Close | F63: VMC % Change | G63: SPY & Change | H63: XLB % Change | I63: Cummulative Return VMC | J63: Cummulative SPY return | K63: Cummulative Return XLB | L63: VMC Normalized | M63: SPY Normalized | N63: XLB Normalized | O63: VMC Relative vs SPY | P63: VMC Relative vs XLB | Q63: VMC Wealth Index | R63: VMC Running Peak | S63: VMC Drawdown | T63: VMC EMA200 | U63: VMC EMA50
B64: 44991 | C64: 179.79 | D64: 404.47 | E64: 41.615 | I64: 0 | J64: 0 | K64: 0 | L64: =(C64/$C$64)*100 -> 100 | M64: =(D64/$D$64)*100 -> 100 | N64: =(E64/$E$64)*100 -> 100 | O64: =(1+I64)/(1+J64)-1 -> 0 | P64: =(1+I64)/(1+K64)-1 -> 0 | Q64: 1 | R64: 1 | S64: 0 | T64: =C64 -> 179.79 | U64: =C64 -> 179.79
B65: 44992 | C65: 177.23 | D65: 398.27 | E65: 40.795 | F65: =C65/C64-1 -> -0.014238834 | G65: =D65/D64 - 1 -> -0.015328702 | H65: =E65/E64 - 1 -> -0.019704433 | I65: =(1+F65)*(1+I64)-1 -> -0.014238834 | J65: =(1+G65)*(1+J64)-1 -> -0.015328702 | K65: =(1+H65)*(1+K64)-1 -> -0.019704433 | L65: =(C65/$C$64)*100 -> 98.576117 | M65: =(D65/$D$64)*100 -> 98.46713 | N65: =(E65/$E$64)*100 -> 98.029557 | O65: =(1+I65)/(1+J65)-1 -> 0.0011068339 | P65: =(1+I65)/(1+K65)-1 -> 0.0055754606 | Q65: =Q64*(1+F65) -> 0.98576117 | R65: =MAX(Q65,R64) -> 1 | S65: =Q65/R65-1 -> -0.014238834 | T65: =C65*'1. Share_Price_Analysis'!$E$11+T64*(1-'1. Share_Price_Analysis'!$E$11) -> 179.76453 | U65: =C65*$L$5+U64*(1-$L$5) -> 179.68961
B66: 44993 | C66: 178.92 | D66: 398.92 | E66: 40.995 | F66: =C66/C65-1 -> 0.0095356317 | G66: =D66/D65 - 1 -> 0.0016320587 | H66: =E66/E65 - 1 -> 0.0049025616 | I66: =(1+F66)*(1+I65)-1 -> -0.0048389788 | J66: =(1+G66)*(1+J65)-1 -> -0.01372166 | K66: =(1+H66)*(1+K65)-1 -> -0.014898474 | L66: =(C66/$C$64)*100 -> 99.516102 | M66: =(D66/$D$64)*100 -> 98.627834 | N66: =(E66/$E$64)*100 -> 98.510153 | O66: =(1+I66)/(1+J66)-1 -> 0.0090062625 | P66: =(1+I66)/(1+K66)-1 -> 0.010211633 | Q66: =Q65*(1+F66) -> 0.99516102 | R66: =MAX(Q66,R65) -> 1 | S66: =Q66/R66-1 -> -0.0048389788 | T66: =C66*'1. Share_Price_Analysis'!$E$11+T65*(1-'1. Share_Price_Analysis'!$E$11) -> 179.75612 | U66: =C66*$L$5+U65*(1-$L$5) -> 179.65943
B67: 44994 | C67: 174.07 | D67: 391.56 | E67: 39.94 | F67: =C67/C66-1 -> -0.027107087 | G67: =D67/D66 - 1 -> -0.018449814 | H67: =E67/E66 - 1 -> -0.025734846 | I67: =(1+F67)*(1+I66)-1 -> -0.031814895 | J67: =(1+G67)*(1+J66)-1 -> -0.031918313 | K67: =(1+H67)*(1+K66)-1 -> -0.04024991 | L67: =(C67/$C$64)*100 -> 96.81851 | M67: =(D67/$D$64)*100 -> 96.808169 | N67: =(E67/$E$64)*100 -> 95.975009 | O67: =(1+I67)/(1+J67)-1 -> 0.00010682745 | P67: =(1+I67)/(1+K67)-1 -> 0.0087887616 | Q67: =Q66*(1+F67) -> 0.9681851 | R67: =MAX(Q67,R66) -> 1 | S67: =Q67/R67-1 -> -0.031814895 | T67: =C67*'1. Share_Price_Analysis'!$E$11+T66*(1-'1. Share_Price_Analysis'!$E$11) -> 179.69955 | U67: =C67*$L$5+U66*(1-$L$5) -> 179.44023
B68: 44995 | C68: 169.29 | D68: 385.91 | E68: 39.09 | F68: =C68/C67-1 -> -0.027460217 | G68: =D68/D67 - 1 -> -0.014429462 | H68: =E68/E67 - 1 -> -0.021281923 | I68: =(1+F68)*(1+I67)-1 -> -0.058401468 | J68: =(1+G68)*(1+J67)-1 -> -0.04588721 | K68: =(1+H68)*(1+K67)-1 -> -0.060675237 | L68: =(C68/$C$64)*100 -> 94.159853 | M68: =(D68/$D$64)*100 -> 95.411279 | N68: =(E68/$E$64)*100 -> 93.932476 | O68: =(1+I68)/(1+J68)-1 -> -0.01311612 | P68: =(1+I68)/(1+K68)-1 -> 0.0024206419 | Q68: =Q67*(1+F68) -> 0.94159853 | R68: =MAX(Q68,R67) -> 1 | S68: =Q68/R68-1 -> -0.058401468 | T68: =C68*'1. Share_Price_Analysis'!$E$11+T67*(1-'1. Share_Price_Analysis'!$E$11) -> 179.59597 | U68: =C68*$L$5+U67*(1-$L$5) -> 179.04219
B69: 44998 | C69: 165.98 | D69: 385.36 | E69: 38.69 | F69: =C69/C68-1 -> -0.019552248 | G69: =D69/D68 - 1 -> -0.0014252028 | H69: =E69/E68 - 1 -> -0.010232796 | I69: =(1+F69)*(1+I68)-1 -> -0.076811836 | J69: =(1+G69)*(1+J68)-1 -> -0.047247015 | K69: =(1+H69)*(1+K68)-1 -> -0.070287156 | L69: =(C69/$C$64)*100 -> 92.318816 | M69: =(D69/$D$64)*100 -> 95.275299 | N69: =(E69/$E$64)*100 -> 92.971284 | O69: =(1+I69)/(1+J69)-1 -> -0.031030941 | P69: =(1+I69)/(1+K69)-1 -> -0.0070179518 | Q69: =Q68*(1+F69) -> 0.92318816 | R69: =MAX(Q69,R68) -> 1 | S69: =Q69/R69-1 -> -0.076811836 | T69: =C69*'1. Share_Price_Analysis'!$E$11+T68*(1-'1. Share_Price_Analysis'!$E$11) -> 179.46049 | U69: =C69*$L$5+U68*(1-$L$5) -> 178.52994
B70: 44999 | C70: 167.51 | D70: 391.73 | E70: 39.185 | F70: =C70/C69-1 -> 0.0092179781 | G70: =D70/D69 - 1 -> 0.016529998 | H70: =E70/E69 - 1 -> 0.012794004 | I70: =(1+F70)*(1+I69)-1 -> -0.068301908 | J70: =(1+G70)*(1+J69)-1 -> -0.03149801 | K70: =(1+H70)*(1+K69)-1 -> -0.058392407 | L70: =(C70/$C$64)*100 -> 93.169809 | M70: =(D70/$D$64)*100 -> 96.850199 | N70: =(E70/$E$64)*100 -> 94.160759 | O70: =(1+I70)/(1+J70)-1 -> -0.038000849 | P70: =(1+I70)/(1+K70)-1 -> -0.010524024 | Q70: =Q69*(1+F70) -> 0.93169809 | R70: =MAX(Q70,R69) -> 1 | S70: =Q70/R70-1 -> -0.068301908 | T70: =C70*'1. Share_Price_Analysis'!$E$11+T69*(1-'1. Share_Price_Analysis'!$E$11) -> 179.34158 | U70: =C70*$L$5+U69*(1-$L$5) -> 178.09779
B71: 45000 | C71: 162.81 | D71: 389.28 | E71: 37.915 | F71: =C71/C70-1 -> -0.028058026 | G71: =D71/D70 - 1 -> -0.0062543078 | H71: =E71/E70 - 1 -> -0.032410361 | I71: =(1+F71)*(1+I70)-1 -> -0.094443517 | J71: =(1+G71)*(1+J70)-1 -> -0.037555319 | K71: =(1+H71)*(1+K70)-1 -> -0.088910249 | L71: =(C71/$C$64)*100 -> 90.555648 | M71: =(D71/$D$64)*100 -> 96.244468 | N71: =(E71/$E$64)*100 -> 91.108975 | O71: =(1+I71)/(1+J71)-1 -> -0.059108019 | P71: =(1+I71)/(1+K71)-1 -> -0.0060732422 | Q71: =Q70*(1+F71) -> 0.90555648 | R71: =MAX(Q71,R70) -> 1 | S71: =Q71/R71-1 -> -0.094443517 | T71: =C71*'1. Share_Price_Analysis'!$E$11+T70*(1-'1. Share_Price_Analysis'!$E$11) -> 179.17708 | U71: =C71*$L$5+U70*(1-$L$5) -> 177.49827
B72: 45001 | C72: 166.21 | D72: 396.11 | E72: 38.35 | F72: =C72/C71-1 -> 0.020883238 | G72: =D72/D71 - 1 -> 0.017545212 | H72: =E72/E71 - 1 -> 0.011473032 | I72: =(1+F72)*(1+I71)-1 -> -0.075532566 | J72: =(1+G72)*(1+J71)-1 -> -0.020669024 | K72: =(1+H72)*(1+K71)-1 -> -0.078457287 | L72: =(C72/$C$64)*100 -> 92.446743 | M72: =(D72/$D$64)*100 -> 97.933098 | N72: =(E72/$E$64)*100 -> 92.154271 | O72: =(1+I72)/(1+J72)-1 -> -0.056021451 | P72: =(1+I72)/(1+K72)-1 -> 0.003173723 | Q72: =Q71*(1+F72) -> 0.92446743 | R72: =MAX(Q72,R71) -> 1 | S72: =Q72/R72-1 -> -0.075532566 | T72: =C72*'1. Share_Price_Analysis'!$E$11+T71*(1-'1. Share_Price_Analysis'!$E$11) -> 179.04806 | U72: =C72*$L$5+U71*(1-$L$5) -> 177.05559
B73: 45002 | C73: 161.02 | D73: 389.99 | E73: 37.755 | F73: =C73/C72-1 -> -0.031225558 | G73: =D73/D72 - 1 -> -0.015450254 | H73: =E73/E72 - 1 -> -0.015514993 | I73: =(1+F73)*(1+I72)-1 -> -0.10439958 | J73: =(1+G73)*(1+J72)-1 -> -0.035799936 | K73: =(1+H73)*(1+K72)-1 -> -0.092755016 | L73: =(C73/$C$64)*100 -> 89.560042 | M73: =(D73/$D$64)*100 -> 96.420006 | N73: =(E73/$E$64)*100 -> 90.724498 | O73: =(1+I73)/(1+J73)-1 -> -0.071146688 | P73: =(1+I73)/(1+K73)-1 -> -0.012835079 | Q73: =Q72*(1+F73) -> 0.89560042 | R73: =MAX(Q73,R72) -> 1 | S73: =Q73/R73-1 -> -0.10439958 | T73: =C73*'1. Share_Price_Analysis'!$E$11+T72*(1-'1. Share_Price_Analysis'!$E$11) -> 178.86867 | U73: =C73*$L$5+U72*(1-$L$5) -> 176.42674
B74: 45005 | C74: 163.27 | D74: 393.74 | E74: 38.365 | F74: =C74/C73-1 -> 0.013973419 | G74: =D74/D73 - 1 -> 0.0096156312 | H74: =E74/E73 - 1 -> 0.0161568 | I74: =(1+F74)*(1+I73)-1 -> -0.091884977 | J74: =(1+G74)*(1+J73)-1 -> -0.026528544 | K74: =(1+H74)*(1+K73)-1 -> -0.07809684 | L74: =(C74/$C$64)*100 -> 90.811502 | M74: =(D74/$D$64)*100 -> 97.347146 | N74: =(E74/$E$64)*100 -> 92.190316 | O74: =(1+I74)/(1+J74)-1 -> -0.067137493 | P74: =(1+I74)/(1+K74)-1 -> -0.014956166 | Q74: =Q73*(1+F74) -> 0.90811502 | R74: =MAX(Q74,R73) -> 1 | S74: =Q74/R74-1 -> -0.091884977 | T74: =C74*'1. Share_Price_Analysis'!$E$11+T73*(1-'1. Share_Price_Analysis'!$E$11) -> 178.71346 | U74: =C74*$L$5+U73*(1-$L$5) -> 175.91079
B75: 45006 | C75: 166.14 | D75: 398.91 | E75: 38.83 | F75: =C75/C74-1 -> 0.017578245 | G75: =D75/D74 - 1 -> 0.013130492 | H75: =E75/E74 - 1 -> 0.012120422 | I75: =(1+F75)*(1+I74)-1 -> -0.075921909 | J75: =(1+G75)*(1+J74)-1 -> -0.013746384 | K75: =(1+H75)*(1+K74)-1 -> -0.066922985 | L75: =(C75/$C$64)*100 -> 92.407809 | M75: =(D75/$D$64)*100 -> 98.625362 | N75: =(E75/$E$64)*100 -> 93.307702 | O75: =(1+I75)/(1+J75)-1 -> -0.063042126 | P75: =(1+I75)/(1+K75)-1 -> -0.0096443533 | Q75: =Q74*(1+F75) -> 0.92407809 | R75: =MAX(Q75,R74) -> 1 | S75: =Q75/R75-1 -> -0.075921909 | T75: =C75*'1. Share_Price_Analysis'!$E$11+T74*(1-'1. Share_Price_Analysis'!$E$11) -> 178.58835 | U75: =C75*$L$5+U74*(1-$L$5) -> 175.52762
B76: 45007 | C76: 163.71 | D76: 392.11 | E76: 38.14 | F76: =C76/C75-1 -> -0.014626219 | G76: =D76/D75 - 1 -> -0.017046452 | H76: =E76/E75 - 1 -> -0.017769766 | I76: =(1+F76)*(1+I75)-1 -> -0.089437677 | J76: =(1+G76)*(1+J75)-1 -> -0.030558509 | K76: =(1+H76)*(1+K75)-1 -> -0.083503544 | L76: =(C76/$C$64)*100 -> 91.056232 | M76: =(D76/$D$64)*100 -> 96.944149 | N76: =(E76/$E$64)*100 -> 91.649646 | O76: =(1+I76)/(1+J76)-1 -> -0.060735144 | P76: =(1+I76)/(1+K76)-1 -> -0.0064748018 | Q76: =Q75*(1+F76) -> 0.91056232 | R76: =MAX(Q76,R75) -> 1 | S76: =Q76/R76-1 -> -0.089437677 | T76: =C76*'1. Share_Price_Analysis'!$E$11+T75*(1-'1. Share_Price_Analysis'!$E$11) -> 178.44031 | U76: =C76*$L$5+U75*(1-$L$5) -> 175.06419
... B814: 46084 | C814: 300 | D814: 680.33 | E814: 51.94 | F814: =C814/C813-1 -> -0.020248204 | G814: =D814/D813 - 1 -> -0.0088143594 | H814: =E814/E813 - 1 -> -0.024600939 | I814: =(1+F814)*(1+I813)-1 -> 0.66861338 | J814: =(1+G814)*(1+J813)-1 -> 0.68202833 | K814: =(1+H814)*(1+K813)-1 -> 0.24810765 | L814: =(C814/$C$64)*100 -> 166.86134 | M814: =(D814/$D$64)*100 -> 168.20283 | N814: =(E814/$E$64)*100 -> 124.81077 | O814: =(1+I814)/(1+J814)-1 -> -0.0079754608 | P814: =(1+I814)/(1+K814)-1 -> 0.33691463 | Q814: =Q813*(1+F814) -> 1.6686134 | R814: =MAX(Q814,R813) -> 1.8375327 | S814: =Q814/R814-1 -> -0.091927233 | T814: =C814*'1. Share_Price_Analysis'!$E$11+T813*(1-'1. Share_Price_Analysis'!$E$11) -> 289.80305 | U814: =C814*$L$5+U813*(1-$L$5) -> 305.05759
B815: 46085 | C815: 295.98 | D815: 685.13 | E815: 51.92 | F815: =C815/C814-1 -> -0.0134 | G815: =D815/D814 - 1 -> 0.0070553996 | H815: =E815/E814 - 1 -> -0.00038505968 | I815: =(1+F815)*(1+I814)-1 -> 0.64625396 | J815: =(1+G815)*(1+J814)-1 -> 0.69389572 | K815: =(1+H815)*(1+K814)-1 -> 0.24762706 | L815: =(C815/$C$64)*100 -> 164.6254 | M815: =(D815/$D$64)*100 -> 169.38957 | N815: =(E815/$E$64)*100 -> 124.76271 | O815: =(1+I815)/(1+J815)-1 -> -0.028125552 | P815: =(1+I815)/(1+K815)-1 -> 0.31950806 | Q815: =Q814*(1+F815) -> 1.646254 | R815: =MAX(Q815,R814) -> 1.8375327 | S815: =Q815/R815-1 -> -0.10409541

Sheet 2. Financial_Analyst
B1: Sheet2_Financial_Analyst
B2: Horizental Analysis
B3: Year | C3: 2021 | D3: 2022 | E3: 2023 | F3: 2024 | G3: 2025 | H3: 2022 YoY | I3: 2023 YoY | J3: 2024 YoY | K3: 2025 YoY | L3: 4Y CAGR
B4: Income Statement | U4: Company | V4: MLM | W4: EXP | X4: VMC | Y4: CRH | Z4: KNF | AA4: CX
B5: Revenue | C5: ='9. Standardlized_Income'!H34 -> 5552.2 | D5: ='9. Standardlized_Income'!G34 -> 7315.2 | E5: ='9. Standardlized_Income'!F34 -> 7781.9 | F5: ='9. Standardlized_Income'!E34 -> 7417.7 | G5: ='9. Standardlized_Income'!D34 -> 7941.1 | H5: =D5/C5-1 -> 0.31753179 | I5: =E5/D5-1 -> 0.063798666 | J5: =F5/E5-1 -> -0.04680091 | K5: =G5/F5-1 -> 0.070560956 | L5: =(G5/C5)^(1/4)-1 -> 0.09358839 | U5: EBITDA Margin | V5: ='9. Standardlized_Income'!J46/'9. Standardlized_Income'!J34 -> 0.34634146 | W5: ='9. Standardlized_Income'!R46/'9. Standardlized_Income'!R34 -> 0.33820686 | X5: ='9. Standardlized_Income'!D46/'9. Standardlized_Income'!D34 -> 0.28659757 | Y5: ='9. Standardlized_Income'!N46/'9. Standardlized_Income'!N34 -> 0.19972227 | Z5: ='9. Standardlized_Income'!L46/'9. Standardlized_Income'!L34 -> 0.15613746 | AA5: ='9. Standardlized_Income'!P46/'9. Standardlized_Income'!P34 -> 0.14231323
B6: Cost of Revenues | C6: ='9. Standardlized_Income'!H35 -> 4178.8 | D6: ='9. Standardlized_Income'!G35 -> 5757.5 | E6: ='9. Standardlized_Income'!F35 -> 5833.4 | F6: ='9. Standardlized_Income'!E35 -> 5418.1 | G6: ='9. Standardlized_Income'!D35 -> 5766.5 | H6: =D6/C6-1 -> 0.37778788 | I6: =E6/D6-1 -> 0.013182805 | J6: =F6/E6-1 -> -0.071193472 | K6: =G6/F6-1 -> 0.064302984 | L6: =(G6/C6)^(1/4)-1 -> 0.083840007
B7: Gross Profit | C7: =C5-C6 -> 1373.4 | D7: =D5-D6 -> 1557.7 | E7: =E5-E6 -> 1948.5 | F7: =F5-F6 -> 1999.6 | G7: =G5-G6 -> 2174.6 | H7: =D7/C7-1 -> 0.13419251 | I7: =E7/D7-1 -> 0.25088271 | J7: =F7/E7-1 -> 0.026225302 | K7: =G7/F7-1 -> 0.087517504 | L7: =(G7/C7)^(1/4)-1 -> 0.12174873 | U7: Metric | V7: MLM | W7: EXP | X7: VMC | Y7: CRH | Z7: KNF | AA7: CX
B8: SG&A | C8: ='9. Standardlized_Income'!H37 -> 417.6 | D8: ='9. Standardlized_Income'!G37 -> 515.1 | E8: ='9. Standardlized_Income'!F37 -> 542.8 | F8: ='9. Standardlized_Income'!E37 -> 531.1 | G8: ='9. Standardlized_Income'!D37 -> 564.1 | H8: =D8/C8-1 -> 0.23347701 | I8: =E8/D8-1 -> 0.053775966 | J8: =F8/E8-1 -> -0.021554901 | K8: =G8/F8-1 -> 0.062135191 | L8: =(G8/C8)^(1/4)-1 -> 0.07807482 | U8: EBITDA Margin | V8: ='9. Standardlized_Income'!J46/'9. Standardlized_Income'!J34 -> 0.34634146 | W8: ='9. Standardlized_Income'!R46/'9. Standardlized_Income'!R34 -> 0.33820686 | X8: ='9. Standardlized_Income'!D46/'9. Standardlized_Income'!D34 -> 0.28659757 | Y8: ='9. Standardlized_Income'!N46/'9. Standardlized_Income'!N34 -> 0.19972227 | Z8: ='9. Standardlized_Income'!L46/'9. Standardlized_Income'!L34 -> 0.15613746 | AA8: ='9. Standardlized_Income'!P46/'9. Standardlized_Income'!P34 -> 0.14231323
B9: Other Operating (Income) / Expense | C9: ='9. Standardlized_Income'!H38 -> -15.9 | D9: ='9. Standardlized_Income'!G38 -> 13.1 | E9: ='9. Standardlized_Income'!F38 -> 83.5 | F9: ='9. Standardlized_Income'!E38 -> 72.4 | G9: ='9. Standardlized_Income'!D38 -> 83.1 | H9: =D9/C9-1 -> -1.8238994 | I9: =E9/D9-1 -> 5.3740458 | J9: =F9/E9-1 -> -0.13293413 | K9: =G9/F9-1 -> 0.14779006 | L9: Not Meaningful | U9: EBIT Margin | V9: ='9. Standardlized_Income'!J39/'9. Standardlized_Income'!J34 -> 0.24276423 | W9: ='9. Standardlized_Income'!R39/'9. Standardlized_Income'!R34 -> 0.26791299 | X9: ='9. Standardlized_Income'!D39/'9. Standardlized_Income'!D34 -> 0.19234111 | Y9: ='9. Standardlized_Income'!N39/'9. Standardlized_Income'!N34 -> 0.14214757 | Z9: ='9. Standardlized_Income'!L39/'9. Standardlized_Income'!L34 -> 0.09455469 | AA9: ='9. Standardlized_Income'!P39/'9. Standardlized_Income'!P34 -> 0.062289702
B10: EBITDA | C10: =C11+'9. Standardlized_Income'!H47 -> 1434.7 | D10: =D11+'9. Standardlized_Income'!G47 -> 1617 | E10: =E11+'9. Standardlized_Income'!F47 -> 1939.2 | F10: =F11+'9. Standardlized_Income'!E47 -> 2028.3 | G10: =G11+'9. Standardlized_Income'!D47 -> 2275.9 | H10: =D10/C10-1 -> 0.12706489 | I10: =E10/D10-1 -> 0.19925788 | J10: =F10/E10-1 -> 0.045946782 | K10: =G10/F10-1 -> 0.12207267 | L10: =(G10/C10)^(1/4)-1 -> 0.12227172 | U10: Net Margin | V10: ='9. Standardlized_Income'!J44/'9. Standardlized_Income'!J34 -> 0.18487805 | W10: ='9. Standardlized_Income'!R44/'9. Standardlized_Income'!R34 -> 0.20500683 | X10: ='9. Standardlized_Income'!D44/'9. Standardlized_Income'!D34 -> 0.13558575 | Y10: ='9. Standardlized_Income'!N44/'9. Standardlized_Income'!N34 -> 0.10022165 | Z10: ='9. Standardlized_Income'!L44/'9. Standardlized_Income'!L34 -> 0.049926733 | AA10: ='9. Standardlized_Income'!P44/'9. Standardlized_Income'!P34 -> 0.059519411
B11: EBIT | C11: =C7-C8-C9 -> 971.7 | D11: =D7-D8-D9 -> 1029.5 | E11: =E7-E8-E9 -> 1322.2 | F11: =F7-F8-F9 -> 1396.1 | G11: =G7-G8-G9 -> 1527.4 | H11: =D11/C11-1 -> 0.05948338 | I11: =E11/D11-1 -> 0.28431277 | J11: =F11/E11-1 -> 0.055891696 | K11: =G11/F11-1 -> 0.094047704 | L11: =(G11/C11)^(1/4)-1 -> 0.11970894
B12: Net Income | C12: ='9. Standardlized_Income'!H44 -> 670.8 | D12: ='9. Standardlized_Income'!G44 -> 575.6 | E12: ='9. Standardlized_Income'!F44 -> 933.2 | F12: ='9. Standardlized_Income'!E44 -> 911.9 | G12: ='9. Standardlized_Income'!D44 -> 1076.7 | H12: =D12/C12-1 -> -0.1419201 | I12: =E12/D12-1 -> 0.62126477 | J12: =F12/E12-1 -> -0.022824689 | K12: =G12/F12-1 -> 0.18072157 | L12: =(G12/C12)^(1/4)-1 -> 0.12557753 | N12: =C12/C11 -> 0.69033652 | U12: Metric | V12: MLM | W12: EXP | X12: VMC | Y12: CRH | Z12: KNF | AA12: CX
U13: Debt/Equity | V13: ='9. Standardlized_Income'!J31/'9. Standardlized_Income'!J30 -> 0.56059398 | W13: ='9. Standardlized_Income'!R31/'9. Standardlized_Income'!R30 -> 0.85008581 | X13: ='9. Standardlized_Income'!D31/'9. Standardlized_Income'!D30 -> 0.5115161 | Y13: ='9. Standardlized_Income'!N31/'9. Standardlized_Income'!N30 -> 0.72608592 | Z13: ='9. Standardlized_Income'!L31/'9. Standardlized_Income'!L30 -> 0.71028801 | AA13: ='9. Standardlized_Income'!P31/'9. Standardlized_Income'!P30 -> 0.49773523
B14: Balance Sheet | U14: Debt/Assets | V14: ='9. Standardlized_Income'!J31/'9. Standardlized_Income'!J17 -> 0.3006253 | W14: ='9. Standardlized_Income'!R31/'9. Standardlized_Income'!R17 -> 0.37931869 | X14: ='9. Standardlized_Income'!D31/'9. Standardlized_Income'!D17 -> 0.26184403 | Y14: ='9. Standardlized_Income'!N31/'9. Standardlized_Income'!N17 -> 0.31180031 | Z14: ='9. Standardlized_Income'!L31/'9. Standardlized_Income'!L17 -> 0.3193164 | AA14: ='9. Standardlized_Income'!P31/'9. Standardlized_Income'!P17 -> 0.23407114
B15: Cash & ST Investments | C15: ='9. Standardlized_Income'!H8 -> 235 | D15: ='9. Standardlized_Income'!G8 -> 161.4 | E15: ='9. Standardlized_Income'!F8 -> 931.1 | F15: ='9. Standardlized_Income'!E8 -> 559.7 | G15: ='9. Standardlized_Income'!D8 -> 183.3 | H15: =D15/C15-1 -> -0.31319149 | I15: =E15/D15-1 -> 4.7688971 | J15: =F15/E15-1 -> -0.39888304 | K15: =G15/F15-1 -> -0.67250313 | L15: =(G15/C15)^(1/4)-1 -> -0.060225513 | U15: Interest Coverage | V15: ='9. Standardlized_Income'!J39/'9. Standardlized_Income'!J40 -> 6.4913043 | W15: ='9. Standardlized_Income'!R39/'9. Standardlized_Income'!R40 -> 15.050199 | X15: ='9. Standardlized_Income'!D39/'9. Standardlized_Income'!D40 -> 6.3721318 | Y15: ='9. Standardlized_Income'!N39/'9. Standardlized_Income'!N40 -> 6.5716049 | Z15: ='9. Standardlized_Income'!L39/'9. Standardlized_Income'!L40 -> 3.6303393 | AA15: ='9. Standardlized_Income'!P39/'9. Standardlized_Income'!P40 -> 3.3408139
B16: Receivables | C16: ='9. Standardlized_Income'!H9 -> 783.2 | D16: ='9. Standardlized_Income'!G9 -> 845.6 | E16: ='9. Standardlized_Income'!F9 -> 889.7 | F16: ='9. Standardlized_Income'!E9 -> 892.3 | G16: ='9. Standardlized_Income'!D9 -> 887.7 | H16: =D16/C16-1 -> 0.079673136 | I16: =E16/D16-1 -> 0.052152318 | J16: =F16/E16-1 -> 0.0029223334 | K16: =G16/F16-1 -> -0.0051552169 | L16: =(G16/C16)^(1/4)-1 -> 0.031806799
B17: Inventory | C17: ='9. Standardlized_Income'!H10 -> 521.3 | D17: ='9. Standardlized_Income'!G10 -> 579.3 | E17: ='9. Standardlized_Income'!F10 -> 615.6 | F17: ='9. Standardlized_Income'!E10 -> 681.8 | G17: ='9. Standardlized_Income'!D10 -> 680.5 | H17: =D17/C17-1 -> 0.11126031 | I17: =E17/D17-1 -> 0.062661833 | J17: =F17/E17-1 -> 0.10753736 | K17: =G17/F17-1 -> -0.0019067175 | L17: =(G17/C17)^(1/4)-1 -> 0.068895137
B18: Current Assets | C18: ='9. Standardlized_Income'!H12 -> 1696.6 | D18: ='9. Standardlized_Income'!G12 -> 1902 | E18: ='9. Standardlized_Income'!F12 -> 2524.9 | F18: ='9. Standardlized_Income'!E12 -> 2265.7 | G18: ='9. Standardlized_Income'!D12 -> 2567.9 | H18: =D18/C18-1 -> 0.12106566 | I18: =E18/D18-1 -> 0.32749737 | J18: =F18/E18-1 -> -0.10265753 | K18: =G18/F18-1 -> 0.13338041 | L18: =(G18/C18)^(1/4)-1 -> 0.10917395
B19: PP&E, net | C19: ='9. Standardlized_Income'!H13 -> 6238.2 | D19: ='9. Standardlized_Income'!G13 -> 6623.9 | E19: ='9. Standardlized_Income'!F13 -> 6729.4 | F19: ='9. Standardlized_Income'!E13 -> 8987.9 | G19: ='9. Standardlized_Income'!D13 -> 8670.1 | H19: =D19/C19-1 -> 0.061828733 | I19: =E19/D19-1 -> 0.015927173 | J19: =F19/E19-1 -> 0.33561685 | K19: =G19/F19-1 -> -0.035358649 | L19: =(G19/C19)^(1/4)-1 -> 0.085778413
B20: Total Assets | C20: ='9. Standardlized_Income'!H17 -> 13682.6 | D20: ='9. Standardlized_Income'!G17 -> 14234.6 | E20: ='9. Standardlized_Income'!F17 -> 14545.7 | F20: ='9. Standardlized_Income'!E17 -> 17104.8 | G20: ='9. Standardlized_Income'!D17 -> 16700.4 | H20: =D20/C20-1 -> 0.04034321 | I20: =E20/D20-1 -> 0.021855198 | J20: =F20/E20-1 -> 0.17593516 | K20: =G20/F20-1 -> -0.023642486 | L20: =(G20/C20)^(1/4)-1 -> 0.051089168
B21: Payables | C21: ='9. Standardlized_Income'!H19 -> 365.5 | D21: ='9. Standardlized_Income'!G19 -> 454.5 | E21: ='9. Standardlized_Income'!F19 -> 390.4 | F21: ='9. Standardlized_Income'!E19 -> 407 | G21: ='9. Standardlized_Income'!D19 -> 438.5 | H21: =D21/C21-1 -> 0.24350205 | I21: =E21/D21-1 -> -0.1410341 | J21: =F21/E21-1 -> 0.042520492 | K21: =G21/F21-1 -> 0.077395577 | L21: =(G21/C21)^(1/4)-1 -> 0.046575477
B22: Current Liabilities | C22: ='9. Standardlized_Income'!H22 -> 769.3 | D22: ='9. Standardlized_Income'!G22 -> 956.6 | E22: ='9. Standardlized_Income'!F22 -> 797.6 | F22: ='9. Standardlized_Income'!E22 -> 1239.1 | G22: ='9. Standardlized_Income'!D22 -> 956.1 | H22: =D22/C22-1 -> 0.24346809 | I22: =E22/D22-1 -> -0.16621367 | J22: =F22/E22-1 -> 0.55353561 | K22: =G22/F22-1 -> -0.22839157 | L22: =(G22/C22)^(1/4)-1 -> 0.055849203
B23: Total Liabilities | C23: ='9. Standardlized_Income'!H26 -> 7114.9 | D23: ='9. Standardlized_Income'!G26 -> 7282.4 | E23: ='9. Standardlized_Income'!F26 -> 7037.8 | F23: ='9. Standardlized_Income'!E26 -> 8962.3 | G23: ='9. Standardlized_Income'!D26 -> 8151.5 | H23: =D23/C23-1 -> 0.023542144 | I23: =E23/D23-1 -> -0.033587828 | J23: =F23/E23-1 -> 0.27345193 | K23: =G23/F23-1 -> -0.090467849 | L23: =(G23/C23)^(1/4)-1 -> 0.034587396
B24: Total Debt | C24: ='9. Standardlized_Income'!H31 -> 3975.9 | D24: ='9. Standardlized_Income'!G31 -> 4032.8 | E24: ='9. Standardlized_Income'!F31 -> 3906.9 | F24: ='9. Standardlized_Income'!E31 -> 5327.8 | G24: ='9. Standardlized_Income'!D31 -> 4372.9 | H24: =D24/C24-1 -> 0.014311225 | I24: =E24/D24-1 -> -0.031219004 | J24: =F24/E24-1 -> 0.36368988 | K24: =G24/F24-1 -> -0.1792297 | L24: =(G24/C24)^(1/4)-1 -> 0.024079148
B25: Total Equity | C25: ='9. Standardlized_Income'!H30 -> 6567.7 | D25: ='9. Standardlized_Income'!G30 -> 6952.2 | E25: ='9. Standardlized_Income'!F30 -> 7507.9 | F25: ='9. Standardlized_Income'!E30 -> 8142.5 | G25: ='9. Standardlized_Income'!D30 -> 8548.9 | H25: =D25/C25-1 -> 0.058544087 | I25: =E25/D25-1 -> 0.079931532 | J25: =F25/E25-1 -> 0.084524301 | K25: =G25/F25-1 -> 0.049910961 | L25: =(G25/C25)^(1/4)-1 -> 0.068130294
B26: Working Capital | C26: =C18-C22 -> 927.3 | D26: =D18-D22 -> 945.4 | E26: =E18-E22 -> 1727.3 | F26: =F18-F22 -> 1026.6 | G26: =G18-G22 -> 1611.8 | H26: =D26/C26-1 -> 0.019519034 | I26: =E26/D26-1 -> 0.82705733 | J26: =F26/E26-1 -> -0.40566202 | K26: =G26/F26-1 -> 0.57003702 | L26: =(G26/C26)^(1/4)-1 -> 0.1482137
B28: Cash Flow
B29: Operating Cash Flow | C29: ='9. Standardlized_Income'!H51 -> 1011.9 | D29: ='9. Standardlized_Income'!G51 -> 1148.2 | E29: ='9. Standardlized_Income'!F51 -> 1536.8 | F29: ='9. Standardlized_Income'!E51 -> 1409.6 | G29: ='9. Standardlized_Income'!D51 -> 1813 | H29: =D29/C29-1 -> 0.1346971 | I29: =E29/D29-1 -> 0.33844278 | J29: =F29/E29-1 -> -0.082769391 | K29: =G29/F29-1 -> 0.28618048 | L29: =(G29/C29)^(1/4)-1 -> 0.15695123
B30: Capital Expenditures | C30: ='9. Standardlized_Income'!H52 -> 451.3 | D30: ='9. Standardlized_Income'!G52 -> 612.6 | E30: ='9. Standardlized_Income'!F52 -> 872.6 | F30: ='9. Standardlized_Income'!E52 -> 603.5 | G30: ='9. Standardlized_Income'!D52 -> 677.7 | H30: =D30/C30-1 -> 0.35741192 | I30: =E30/D30-1 -> 0.4244205 | J30: =F30/E30-1 -> -0.30838872 | K30: =G30/F30-1 -> 0.12294946 | L30: =(G30/C30)^(1/4)-1 -> 0.10698832
B31: Free Cash Flow | C31: =C29-C30 -> 560.6 | D31: =D29-D30 -> 535.6 | E31: =E29-E30 -> 664.2 | F31: =F29-F30 -> 806.1 | G31: =G29-G30 -> 1135.3 | H31: =D31/C31-1 -> -0.044595077 | I31: =E31/D31-1 -> 0.24010456 | J31: =F31/E31-1 -> 0.21364047 | K31: =G31/F31-1 -> 0.40838606 | L31: =(G31/C31)^(1/4)-1 -> 0.19292842
B33: Vertical Analysis
B34: Income Staetement ( % of Revenue) | H34: Peer Vertical Analysis (FY2025)
B35: Metrics / Year | C35: 2021 | D35: 2022 | E35: 2023 | F35: 2024 | G35: 2025 | H35: MLM | I35: KNF | J35: CRH | K35: CX | L35: EXP
B36: Revenue | C36: =100% -> 1 | D36: =100% -> 1 | E36: =100% -> 1 | F36: =100% -> 1 | G36: =100% -> 1 | H36: 1 | I36: 1 | J36: 1 | K36: 1 | L36: 1
B37: Cost of Revenues | C37: =C6/$C$5 -> 0.75263859 | D37: =D6/D$5 -> 0.78705982 | E37: =E6/E$5 -> 0.74961128 | F37: =F6/F$5 -> 0.73042857 | G37: =G6/G$5 -> 0.72615884 | H37: ='9. Standardlized_Income'!J35/'9. Standardlized_Income'!J34 -> 0.69284553 | I37: ='9. Standardlized_Income'!L35/'9. Standardlized_Income'!L34 -> 0.81648819 | J37: ='9. Standardlized_Income'!N35/'9. Standardlized_Income'!N34 -> 0.63874276 | K37: ='9. Standardlized_Income'!P35/'9. Standardlized_Income'!P34 -> 0.6708065 | L37: ='9. Standardlized_Income'!R35/'9. Standardlized_Income'!R34 -> 0.70221764
B38: Gross Profit | C38: =C7/$C$5 -> 0.24736141 | D38: =D7/$D$5 -> 0.21294018 | E38: =E7/E$5 -> 0.25038872 | F38: =F7/F$5 -> 0.26957143 | G38: =G7/G$5 -> 0.27384116 | H38: ='9. Standardlized_Income'!J36/'9. Standardlized_Income'!J34 -> 0.30715447 | I38: ='9. Standardlized_Income'!L36/'9. Standardlized_Income'!L34 -> 0.18351181 | J38: ='9. Standardlized_Income'!N36/'9. Standardlized_Income'!N34 -> 0.36125724 | K38: ='9. Standardlized_Income'!P36/'9. Standardlized_Income'!P34 -> 0.3291935 | L38: ='9. Standardlized_Income'!R36/'9. Standardlized_Income'!R34 -> 0.29778236
B39: SG&A | C39: =C8/$C$5 -> 0.075213429 | D39: =D8/$D$5 -> 0.070415026 | E39: =E8/E$5 -> 0.069751603 | F39: =F8/F$5 -> 0.071599013 | G39: =G8/G$5 -> 0.071035499 | H39: ='9. Standardlized_Income'!J37/'9. Standardlized_Income'!J34 -> 0.07203252 | I39: ='9. Standardlized_Income'!L37/'9. Standardlized_Income'!L34 -> 0.089208235 | J39: ='9. Standardlized_Income'!N37/'9. Standardlized_Income'!N34 -> 0.21910968 | K39: ='9. Standardlized_Income'!P37/'9. Standardlized_Income'!P34 -> 0.2182864 | L39: ='9. Standardlized_Income'!R37/'9. Standardlized_Income'!R34 -> 0.032709433
B40: Other Operating (Income) / Expense | C40: =C9/$C$5 -> -0.0028637297 | D40: =D9/$D$5 -> 0.0017907918 | E40: =E9/E$5 -> 0.010730027 | F40: =F9/F$5 -> 0.0097604379 | G40: =G9/G$5 -> 0.010464545 | H40: ='9. Standardlized_Income'!J38/'9. Standardlized_Income'!J34 -> -0.0076422764 | I40: ='9. Standardlized_Income'!L38/'9. Standardlized_Income'!L34 -> -0.00025429036 | J40: ='9. Standardlized_Income'!N38/'9. Standardlized_Income'!N34 -> 0 | K40: ='9. Standardlized_Income'!P38/'9. Standardlized_Income'!P34 -> 0.048617396 | L40: ='9. Standardlized_Income'!R38/'9. Standardlized_Income'!R34 -> -0.0028400671
B41: EBITDA Margin | C41: =C10/$C$5 -> 0.25840207 | D41: =D10/$D$5 -> 0.22104659 | E41: =E10/E$5 -> 0.24919364 | F41: =F10/F$5 -> 0.27344055 | G41: =G10/G$5 -> 0.28659757 | H41: ='9. Standardlized_Income'!J46/'9. Standardlized_Income'!J34 -> 0.34634146 | I41: ='9. Standardlized_Income'!L46/'9. Standardlized_Income'!L34 -> 0.15613746 | J41: ='9. Standardlized_Income'!N46/'9. Standardlized_Income'!N34 -> 0.19972227 | K41: ='9. Standardlized_Income'!P46/'9. Standardlized_Income'!P34 -> 0.14231323 | L41: ='9. Standardlized_Income'!R46/'9. Standardlized_Income'!R34 -> 0.33820686
B42: EBIT Margin | C42: =C11/$C$5 -> 0.17501171 | D42: =D11/$D$5 -> 0.14073436 | E42: =E11/E$5 -> 0.16990709 | F42: =F11/F$5 -> 0.18821198 | G42: =G11/G$5 -> 0.19234111 | H42: ='9. Standardlized_Income'!J39/'9. Standardlized_Income'!J34 -> 0.24276423 | I42: ='9. Standardlized_Income'!L39/'9. Standardlized_Income'!L34 -> 0.09455469 | J42: ='9. Standardlized_Income'!N39/'9. Standardlized_Income'!N34 -> 0.14214757 | K42: ='9. Standardlized_Income'!P39/'9. Standardlized_Income'!P34 -> 0.062289702 | L42: ='9. Standardlized_Income'!R39/'9. Standardlized_Income'!R34 -> 0.26791299
...

Sheet 3. Credit_Analysis
B1: Sheet 3 – Credit Analysis | Vulcan Materials Company (VMC)
B3: 1. CREDIT OVERVIEW
B4: Assessment | C4: Rating | D4: Score | E4: Scale | F4: Justification
B5: Business Risk | C5: Low | D5: 2 | E5: 1–5 | F5: Dominant #2 position in US aggregates; irreplaceable, permitted reserves; long asset life; essential-use product with no substitutes
B6: Financial Risk | C6: Low-Moderate | D6: 2 | E6: 1–5 | F6: Debt/EBITDA 1.9x; Net Debt/EBITDA 1.8x; EBITDA/Interest 9.5x; CFO/Debt 41.5% — well within IG thresholds
B7: Liquidity Risk | C7: Strong | D7: 1 | E7: 1–5 | F7: Current Ratio 2.7x; Quick Ratio 2.0x; $183mm cash + $1.6B undrawn revolver; minimal near-term maturities
B8: Cyclicality | C8: Moderate | D8: 3 | E8: 1–5 | F8: Construction-driven demand is cyclical, but mitigated by infrastructure/public spending and pricing power
B9: Industry Position | C9: Strong - #2 US Aggregates | D9: 1 | E9: 1–5 | F9: #2 US aggregates producer; 28.7% EBITDA margin (above median); vertically integrated operations across 25+ states
B10: Overall Credit View | C10: Investment Grade | D10: Avg: 1.8 | E10: IG: ≤ 2.5 | F10: Composite score supports strong Investment Grade profile (BBB+ / Baa1 equivalent)
B12: 2. CAPITAL STRUCTURE SNAPSHOT | I12: Financial Risk - Moderate
B13: ($mm) | C13: 2021 | D13: 2022 | E13: 2023 | F13: 2024 | G13: 2025 | I13: Driver | J13: Evidence | K13: Credit implication
B14: Cash & Equivalents | C14: ='2. Financial_Analyst'!C15 -> 235 | D14: ='2. Financial_Analyst'!D15 -> 161.4 | E14: ='2. Financial_Analyst'!E15 -> 931.1 | F14: ='2. Financial_Analyst'!F15 -> 559.7 | G14: ='2. Financial_Analyst'!G15 -> 183.3 | I14: Leverage | J14: Total Debt / EBITDA fell from 2.8x to 1.9x; Net Debt / EBITDA improved from 2.6x to 1.8x | K14: Manageable leverage profile
B15: Short-Term Debt | C15: ='2. Financial_Analyst'!C24-'[1]Sheet9_Financial Data'!G834 -> 40.6 | D15: ='2. Financial_Analyst'!D24-'[1]Sheet9_Financial Data'!F834 -> 122.8 | E15: ='2. Financial_Analyst'!E24-'[1]Sheet9_Financial Data'!E834 -> 13 | F15: ='2. Financial_Analyst'!F24-'[1]Sheet9_Financial Data'!D834 -> 411.2 | G15: ='2. Financial_Analyst'!G24-'[1]Sheet9_Financial Data'!C834 -> 6.2 | I15: Coverage | J15: EBITDA / Interest remained 9.5x–10.6x; EBIT / Interest 6.1x–7.3x | K15: Strong debt servicing capacity
B16: Long-Term Debt | C16: ='[1]Sheet9_Financial Data'!G834 -> 3935.3 | D16: ='[1]Sheet9_Financial Data'!F834 -> 3910 | E16: ='[1]Sheet9_Financial Data'!E834 -> 3893.9 | F16: ='[1]Sheet9_Financial Data'!D834 -> 4916.6 | G16: ='[1]Sheet9_Financial Data'!C834 -> 4366.7 | I16: Cash Flow | J16: CFO / Total Debt improved to 41.5%; FCF / Total Debt rose to 26.0% | K16: Solid deleveraging and repayment capacity
B17: Total Debt | C17: ='2. Financial_Analyst'!C24 -> 3975.9 | D17: ='2. Financial_Analyst'!D24 -> 4032.8 | E17: ='2. Financial_Analyst'!E24 -> 3906.9 | F17: ='2. Financial_Analyst'!F24 -> 5327.8 | G17: ='2. Financial_Analyst'!G24 -> 4372.9
B18: Net Debt | C18: =C17-C14 -> 3740.9 | D18: =D17-D14 -> 3871.4 | E18: =E17-E14 -> 2975.8 | F18: =F17-F14 -> 4768.1 | G18: =G17-G14 -> 4189.6 | I18: Liquidity Risk - Strong
B19: Total Equity | C19: ='2. Financial_Analyst'!C25 -> 6567.7 | D19: ='2. Financial_Analyst'!D25 -> 6952.2 | E19: ='2. Financial_Analyst'!E25 -> 7507.9 | F19: ='2. Financial_Analyst'!F25 -> 8142.5 | G19: ='2. Financial_Analyst'!G25 -> 8548.9 | I19: Driver | J19: Evidence | K19: Credit implication
B20: Total Capital (Debt + Equity) | C20: =C17+C19 -> 10543.6 | D20: =D17+D19 -> 10985 | E20: =E17+E19 -> 11414.8 | F20: =F17+F19 -> 13470.3 | G20: =G17+G19 -> 12921.8 | I20: Liquidity profile | J20: Current Ratio 1.8x–3.2x; Quick Ratio 1.3x–2.4x | K20: Comfortable short-term coverage
B21: Enterprise Value | G21: =G18+G17-G14 -> 8379.2 | I21: Near-term debt | J21: Short-term debt low in most years; 2025 at $6.2mm | K21: Limited refinancing pressure
B22: Debt / Capital | C22: =C17/C20 -> 0.37709132 | D22: =D17/D20 -> 0.3671188 | E22: =E17/E20 -> 0.34226618 | F22: =F17/F20 -> 0.395522 | G22: =G17/G20 -> 0.33841261 | I22: Cash flow support | J22: CFO / Total Debt up to 41.5% | K22: Strong liquidity support
B23: Equity / Capital | C23: =C19/C20 -> 0.62290868 | D23: =D19/D20 -> 0.6328812 | E23: =E19/E20 -> 0.65773382 | F23: =F19/F20 -> 0.604478 | G23: =G19/G20 -> 0.66158739
I24: Cyclicality - Moderate
B25: 3. HISTORICAL CREDIT METRICS | I25: Driver | J25: Evidence | K25: Implication
B26: Leverage | C26: 2021 | D26: 2022 | E26: 2023 | F26: 2024 | G26: 2025 | I26: End-market exposure | J26: Construction-driven demand; ~60% private / ~40% public mix | K26: Volume sensitive to economic cycle; residential & non-res exposure
B27: Total Debt / EBITDA | C27: ='2. Financial_Analyst'!C24/'2. Financial_Analyst'!C10 -> 2.7712414 | D27: ='2. Financial_Analyst'!D24/'2. Financial_Analyst'!D10 -> 2.4940012 | E27: ='2. Financial_Analyst'!E24/'2. Financial_Analyst'!E10 -> 2.0146968 | F27: ='2. Financial_Analyst'!F24/'2. Financial_Analyst'!F10 -> 2.6267317 | G27: ='2. Financial_Analyst'!G24/'2. Financial_Analyst'!G10 -> 1.9213937 | I27: Demand support | J27: Infrastructure Investment & Jobs Act (IIJA) provides $550B+ in federal spending | K27: Multi-year public demand floor; partial downside buffer in downturns
B28: Net Debt / EBITDA | C28: =C18/'2. Financial_Analyst'!C10 -> 2.6074441 | D28: =D18/'2. Financial_Analyst'!D10 -> 2.3941868 | E28: =E18/'2. Financial_Analyst'!E10 -> 1.5345503 | F28: =F18/'2. Financial_Analyst'!F10 -> 2.3507864 | G28: =G18/'2. Financial_Analyst'!G10 -> 1.8408542 | I28: Earnings resilience | J28: EBITDA margin expanded 280bps (2021–2025) despite volume swings; pricing power intact | K28: Cyclicality moderated by pricing discipline, cost control, and project mix shift
B29: Debt / Equity | C29: =C17/C19 -> 0.60537174 | D29: =D17/D19 -> 0.58007537 | E29: =E17/E19 -> 0.52037187 | F29: =F17/F19 -> 0.65431993 | G29: =G17/G19 -> 0.5115161 | I29: Business Risk - Low
B30: Debt / Capital | C30: =C22 -> 0.37709132 | D30: =D22 -> 0.3671188 | E30: =E22 -> 0.34226618 | F30: =F22 -> 0.395522 | G30: =G22 -> 0.33841261 | I30: Driver | J30: Evidence | K30: Credit implication
I31: Market position | J31: #2 US aggregates producer; operations in 25+ states with irreplaceable, permitted reserves | K31: High barriers to entry; durable competitive advantage
B32: Coverage | I32: Product essentiality | J32: Aggregates are essential inputs for construction with no viable substitutes | K32: Demand is non-discretionary; pricing resilience in downturns
B33: EBITDA / Interest Expense | C33: ='2. Financial_Analyst'!C10/'[1]Sheet9_Financial Data'!G996 -> 9.6095111 | D33: ='2. Financial_Analyst'!D10/'[1]Sheet9_Financial Data'!F996 -> 9.5567376 | E33: ='2. Financial_Analyst'!E10/'[1]Sheet9_Financial Data'!E996 -> 9.8888322 | F33: ='2. Financial_Analyst'!F10/'[1]Sheet9_Financial Data'!D996 -> 10.608264 | G33: ='2. Financial_Analyst'!G10/'[1]Sheet9_Financial Data'!C996 -> 9.4947851 | I33: Margin profile | J33: EBITDA margin expanded from 25.8% (2021) to 28.7% (2025); above peer median | K33: Improving profitability supports cash generation and credit quality
B34: EBIT / Interest Expense | C34: ='2. Financial_Analyst'!C11/'[1]Sheet9_Financial Data'!G996 -> 6.5083724 | D34: ='2. Financial_Analyst'!D11/'[1]Sheet9_Financial Data'!F996 -> 6.0845154 | E34: ='2. Financial_Analyst'!E11/'[1]Sheet9_Financial Data'!E996 -> 6.7424783 | F34: ='2. Financial_Analyst'!F11/'[1]Sheet9_Financial Data'!D996 -> 7.3017782 | G34: ='2. Financial_Analyst'!G11/'[1]Sheet9_Financial Data'!C996 -> 6.3721318 | I34: Geographic diversity | J34: Operations across Sun Belt and high-growth US regions; local market dominance | K34: Reduces concentration risk; benefits from regional growth tailwinds
I35: Revenue visibility | J35: Long-term infrastructure projects (IIJA) provide multi-year demand pipeline | K35: Enhanced earnings predictability and reduced downside volatility
B36: Cash Flow Credit Metrics
B37: CFO / Total Debt | C37: ='2. Financial_Analyst'!C29/'2. Financial_Analyst'!C24 -> 0.25450841 | D37: ='2. Financial_Analyst'!D29/'2. Financial_Analyst'!D24 -> 0.28471533 | E37: ='2. Financial_Analyst'!E29/'2. Financial_Analyst'!E24 -> 0.39335535 | F37: ='2. Financial_Analyst'!F29/'2. Financial_Analyst'!F24 -> 0.2645745 | G37: ='2. Financial_Analyst'!G29/'2. Financial_Analyst'!G24 -> 0.41459901 | I37: Industry Position - Strong
B38: FCF / Total Debt | C38: ='[1]Sheet9_Financial Data'!G1192/'2. Financial_Analyst'!C24 -> 0.14099952 | D38: ='[1]Sheet9_Financial Data'!F1192/'2. Financial_Analyst'!D24 -> 0.13281095 | E38: ='[1]Sheet9_Financial Data'!E1192/'2. Financial_Analyst'!E24 -> 0.17000691 | F38: ='[1]Sheet9_Financial Data'!D1192/'2. Financial_Analyst'!F24 -> 0.15130072 | G38: ='[1]Sheet9_Financial Data'!C1192/'2. Financial_Analyst'!G24 -> 0.25962176 | I38: Driver | J38: Evidence | K38: Credit implication
B39: FCF Yield on Net Debt | C39: ='[1]Sheet9_Financial Data'!G1192/C18 -> 0.14985699 | D39: ='[1]Sheet9_Financial Data'!F1192/D18 -> 0.13834788 | E39: ='[1]Sheet9_Financial Data'!E1192/E18 -> 0.22320048 | F39: ='[1]Sheet9_Financial Data'!D1192/F18 -> 0.16906105 | G39: ='[1]Sheet9_Financial Data'!C1192/G18 -> 0.27098052 | I39: Competitive rank | J39: #2 in US aggregates behind Martin Marietta (MLM); top-3 nationally in asphalt and concrete | K39: Scale advantage enables pricing discipline and cost efficiency
I40: Peer comparison | J40: EBITDA margin 28.7% vs. peer median 24.3%; ROIC 9.2% ranks 3rd of 6 peers | K40: Above-average returns signal superior operational execution
B41: Liquidity | I41: Barriers to entry | J41: Permitting new quarries takes 7–10+ years; proximity to end-markets critical due to high transport cost | K41: Near-unassailable local market positions; limited new entrant threat
B42: Current Ratio | C42: ='2. Financial_Analyst'!C61 -> 2.2053815 | D42: ='2. Financial_Analyst'!D61 -> 1.9882919 | E42: ='2. Financial_Analyst'!E61 -> 3.1656219 | F42: ='2. Financial_Analyst'!F61 -> 1.8285046 | G42: ='2. Financial_Analyst'!G61 -> 2.6858069 | I42: Growth strategy | J42: Disciplined bolt-on M&A (e.g., US Concrete); rapid post-acquisition deleveraging | K42: Accretive growth without compromising credit profile
...

Sheet 4. ESG_Score
A1: Sheet 4 – ESG Score Analysis | Vulcan Materials Company (VMC) | K1: Pillar | L1: Score
K2: Environmental | L2: 55.17
A3: 1. ESG Conclusion & Investment Implications | K3: Social | L3: 60.99
A4: Mid-quality absolute ESG; strong relative to U.S. construction materials peers. Env. and social acceptable; governance is the clear weak spot. | K4: Governance | L4: 20.99
A6: Finding | B6: Score | C6: Implication | K6: Company | L6: ESG Score | M6: Combined
A7: Overall ESG | B7: 49 (C+) | C7: Neutral to slightly positive for base-case | K7: CRH | L7: 84.18 | M7: 76.18
A8: Governance Risk | B8: 21.0 (D+) | C8: Qualitative discount; monitor board improvements | K8: CX | L8: 81.87 | M8: 81.87
A9: Env. Strength | B9: 55.2 (B-) | C9: Supports carbon transition readiness | K9: VMC | L9: 49 | M9: 49
A10: Social Resilience | B10: 61.0 (B) | C10: Helps social license and permitting | K10: MLM | L10: 42.6 | M10: 42.6
A11: Controversies | B11: 68.2 (B+) | C11: FY24 drop; watch for recurrence | K11: KNF | L11: 32.53 | M11: 32.53
A12: Peer Rank | B12: #3 of 6 | C12: Better than MLM/KNF/EXP; trails CRH, CX | K12: EXP | L12: 27.05 | M12: 27.05
A13: Net Impact | C13: Gov. discount partially offset by social/env strengths
K14: Year | L14: ESG Score | M14: Env. | N14: Social | O14: Gov.
A15: 2. ESG Snapshot | K15: FY2020 | L15: 47.42 | M15: 55 | N15: 46.2 | O15: 34
A16: Metric | B16: Score | C16: Grade | D16: Weight | E16: Read-through | K16: FY2021 | L16: 50 | M16: 63 | N16: 44 | O16: 34
A17: ESG Score | B17: 49 | C17: C+ | E17: Moderate overall profile | K17: FY2022 | L17: 47 | M17: 64 | N17: 38 | O17: 31
A18: Controversies | B18: 68.18 | C18: B+ | E18: Safety event drove FY24 drop | K18: FY2023 | L18: 56.15 | M18: 66 | N18: 64 | O18: 29
A19: ESG Combined | B19: 49 | C19: C+ | E19: Combined = headline ESG | K19: FY2024 | L19: 49 | M19: 55.17 | N19: 60.99 | O19: 20.99
A20: Env. Pillar | B20: 55.17 | C20: B- | D20: 0.421 | E20: Best-performing pillar
A21: Social Pillar | B21: 60.99 | C21: B | D21: 0.34 | E21: Resilient; community 87.7
A22: Gov. Pillar | B22: 20.99 | C22: D+ | D22: 0.238 | E22: Structural weakness; main drag
A24: 3. Historical ESG Scorecard (FY2020–FY2024)
A25: Metric | B25: FY2020 | C25: FY2021 | D25: FY2022 | E25: FY2023 | F25: FY2024 | G25: 5Y Avg | H25: YoY Δ | I25: Trend
A26: ESG Score | B26: 47.42 | C26: 50 | D26: 47 | E26: 56.15 | F26: 49 | G26: =AVERAGE(B26:F26) -> 49.914 | H26: =F26-E26 -> -7.15 | I26: Stable
A27: Controversies | B27: 100 | C27: 100 | D27: 50 | E27: 100 | F27: 68.18 | G27: =AVERAGE(B27:F27) -> 83.636 | H27: =F27-E27 -> -31.82 | I27: Deteriorating
A28: ESG Combined | B28: 47.42 | C28: 50 | D28: 47 | E28: 56.15 | F28: 49 | G28: =AVERAGE(B28:F28) -> 49.914 | H28: =F28-E28 -> -7.15 | I28: Stable
A29: Env. Pillar | B29: 55 | C29: 63 | D29: 64 | E29: 66 | F29: 55.17 | G29: =AVERAGE(B29:F29) -> 60.634 | H29: =F29-E29 -> -10.83 | I29: Stable
A30: Social Pillar | B30: 46.2 | C30: 44 | D30: 38 | E30: 64 | F30: 60.99 | G30: =AVERAGE(B30:F30) -> 50.638 | H30: =F30-E30 -> -3.01 | I30: Improving
A31: Gov. Pillar | B31: 34 | C31: 34 | D31: 31 | E31: 29 | F31: 20.99 | G31: =AVERAGE(B31:F31) -> 29.798 | H31: =F31-E31 -> -8.01 | I31: Deteriorating
A32: Diagnostic: | B32: Strongest: Social | Weakest: Governance | Sharpest decline: Controversies (−31.8) | Current ESG below 5Y avg
A34: 4. FY2024 vs FY2023 Pillar Attribution
A35: Pillar | B35: Category | C35: FY2024 | D35: FY2023 | E35: YoY Δ | F35: Weight | G35: Attribution
A36: ESG | B36: ESG Score | C36: 49 | D36: 56.15 | E36: =C36-D36 -> -7.15 | F36: 1 | G36: =E36*F36 -> -7.15
A37: Env. | B37: Resource Use | C37: 43.28 | D37: 45.73 | E37: =C37-D37 -> -2.45 | F37: 0.151 | G37: =E37*F37 -> -0.36995
A38: Env. | B38: Emissions | C38: 59.92 | D38: 61.76 | E38: =C38-D38 -> -1.84 | F38: 0.151 | G38: =E38*F38 -> -0.27784
A39: Env. | B39: Env. Innovation | C39: 64.2 | D39: 95.78 | E39: =C39-D39 -> -31.58 | F39: 0.119 | G39: =E39*F39 -> -3.75802
A40: Social | B40: Workforce | C40: 31.35 | D40: 33.2 | E40: =C40-D40 -> -1.85 | F40: 0.107 | G40: =E40*F40 -> -0.19795
A41: Social | B41: Human Rights | C41: 74.54 | D41: 79.25 | E41: =C41-D41 -> -4.71 | F41: 0.111 | G41: =E41*F41 -> -0.52281
A42: Social | B42: Community | C42: 87.7 | D42: 86 | E42: =C42-D42 -> 1.7 | F42: 0.079 | G42: =E42*F42 -> 0.1343
A43: Social | B43: Product Resp. | C43: 50.41 | D43: 57.08 | E43: =C43-D43 -> -6.67 | F43: 0.042 | G43: =E43*F43 -> -0.28014
...

Sheet 5. Macro-Economics 
B1: Sheet 5 – Macro-Economics & Industry Analysis | Vulcan Materials Company (VMC)
B3: A. Industry Overview — US Aggregates & Construction Materials
B4: A1. Market Summary | C4: Value | D4: Source
B5: US Aggregates Market Size (2024) | C5: 44.8 | D5: USGS / IBISWorld
B6: Industry Cycle Position (2025) | C6: Mid-Cycle / Recovery | D6: IIJA tailwinds offset residential weakness
B7: 3Y Revenue CAGR (FY2022–FY2025) | C7: =('9. Standardlized_Income'!D34/'9. Standardlized_Income'!G34)^(1/3)-1 -> 0.027743693 | D7: Calculated from 9.1
B8: 5Y Revenue CAGR (FY2021–FY2025) | C8: =('9. Standardlized_Income'!D34/'9. Standardlized_Income'!H34)^(1/5)-1 -> 0.074194966 | D8: Calculated from 9.1
B10: A2. Porter's Five Forces | C10: Score (1–5) | D10: Assessment
B11: Threat of New Entrants | C11: 1 | D11: High capex + 5–10yr permitting; reserve scarcity
B12: Supplier Power | C12: 2 | D12: VMC owns quarries; diesel ~8% COGS is key input
B13: Buyer Power | C13: 3 | D13: Fragmented contractors; public-sector bidding limits pricing
B14: Threat of Substitutes | C14: 1 | D14: No viable substitute for road/bridge base (<5% recycled)
B15: Competitive Rivalry | C15: 3 | D15: Effective duopoly with MLM; rational pricing discipline
B17: A3. Industry Structure | C17: Value | D17: Source
B18: US Aggregate Consumption (2024) | C18: ~2.6 Bt | D18: USGS — 23% below pre-GFC peak
B19: Volume CAGR (2014–2024) | C19: ~1.0–1.4% | D19: Crushed stone 1.4%; Sand 0.7%
B20: Value CAGR (ASP, 2014–2024) | C20: ~5.5% | D20: ASP: $9.26→$15.88/ton (USGS)
B21: Forecast CAGR (2025–2033) | C21: ~3.4–6.4% | D21: Range across research sources
B22: Infrastructure End-Use Share | C22: ~38% | D22: Roads/bridges = ~70% of crushed stone
B23: Non-Residential Share | C23: ~55%+ | D23: Infra + commercial/industrial
B24: Residential Share | C24: ~25% | D24: Smallest; fastest-growing (5.1% CAGR)
B26: B. Growth Drivers & Headwinds — VMC
B27: B1. Growth Drivers | F27: B2. Headwinds / Risks
B28: IIJA & Infrastructure | C28: $550B+ federal program; ~30% VMC volumes | F28: Residential Slowdown | G28: Starts -5% in 2024; ~20% VMC volumes
B29: Pricing Power | C29: ASP +14%/+12%/+6% (2022–24); reserve scarcity | F29: Energy Cost Inflation | G29: Diesel ~8% COGS; $0.10/gal = ~$6M EBITDA hit
B30: Reshoring / CHIPS Act | C30: Record industrial construction; fabs & EV plants | F30: Interest Rate Sensitivity | G30: Municipal bond costs limit project starts
B31: M&A Bolt-ons | C31: ~25 quarry acquisitions 2019–24; Sun Belt focus | F31: Weather & Seasonality | G31: 1 lost workday ≈ $15M revenue
B32: Margin Expansion | C32: EBITDA/ton improving via SAP, AI dispatch, leverage | F32: Permitting / Environmental | G32: Avg permit >7 yrs; limits greenfield response
B34: C. Regulatory & Technology Risk
B35: Risk | C35: Probability | D35: Revenue at Risk | E35: Time Horizon | F35: Mitigation
B36: IIJA Funding Delays | C36: M | D36: ~$0.5–1.0B | E36: 2025–27 | F36: Multi-year highway bill + state match = 2yr buffer
B37: EPA Quarry Discharge Rules | C37: M | D37: ~$0.2–0.4B | E37: 2026–28 | F37: Proactive compliance; NSSGA lobbying
B38: Carbon Pricing / Emissions | C38: L | D38: ~$0.1–0.3B | E38: 2028+ | F38: Low-emission vs cement; net-zero 2050 target
B39: AI / Automation Disruption | C39: L | D39: <$0.1B | E39: 2028+ | F39: VMC investing; reduces costs not revenue
B40: Diesel / Energy Shock | C40: H | D40: ~$0.3–0.5B | E40: Immediate | F40: Fleet electrification; hedging; ASP surcharges
B41: Permitting Reform Reversal | C41: M | D41: ~$0.5–1.0B | E41: 2026+ | F41: Reserve runway 65+ yrs; existing permits sufficient
B43: D. Competitive Landscape
B44: Company | C44: Revenue ($mm) | D44: EBITDA Margin | E44: Net Margin | F44: Debt/Assets | G44: ROIC | H44: Interest Cov. | I44: Competitive Position
B45: VMC (Vulcan Materials) | C45: ='9. Standardlized_Income'!D34 -> 7941.1 | D45: ='9. Standardlized_Income'!D46/'9. Standardlized_Income'!D34 -> 0.28659757 | E45: ='9. Standardlized_Income'!D44/'9. Standardlized_Income'!D34 -> 0.13558575 | F45: ='9. Standardlized_Income'!D31/'9. Standardlized_Income'!D17 -> 0.26184403 | G45: ='9. Standardlized_Income'!D44/'9. Standardlized_Income'!D17 -> 0.06447151 | H45: ='9. Standardlized_Income'!D39/'9. Standardlized_Income'!D40 -> 6.3721318 | I45: No.2 US crushed stone; 25+ states; vertically integrated
B46: MLM (Martin Marietta) | C46: ='9. Standardlized_Income'!J34 -> 6150 | D46: ='9. Standardlized_Income'!J46/'9. Standardlized_Income'!J34 -> 0.34634146 | E46: ='9. Standardlized_Income'!J44/'9. Standardlized_Income'!J34 -> 0.18487805 | F46: ='9. Standardlized_Income'!J31/'9. Standardlized_Income'!J17 -> 0.3006253 | G46: ='9. Standardlized_Income'!J44/'9. Standardlized_Income'!J17 -> 0.060766394 | H46: ='9. Standardlized_Income'!J39/'9. Standardlized_Income'!J40 -> 6.4913043 | I46: No.1 US crushed stone; duopoly with VMC; SE/SW focus
...

Sheet 6. Mutliple_Valuation
B1: SHEET 6: MULTIPLE VALUATION
B2: A. Valuation Framework & Multiple Selection
B3: Multiple | C3: Role | D3: Rationale
B4: EV / EBITDA | C4: Primary | D4: Best proxy for operating cash flow; normalizes D&A across asset-heavy quarrying peers with different reserve lives
B5: EV / Revenue | C5: Secondary | D5: Captures pricing power and margin differences; less volatile than earnings; useful for cross-border peers (CRH, CX)
B6: P / E | C6: Cross-check | D6: Widely followed but distorted by D&A, interest costs, and one-offs; used as market sentiment gauge only
B7: EV / EBIT | C7: Excluded | D7: Penalizes high-D&A operators; reserve depletion and quarry amortization inflate D&A beyond economic depreciation
B9: B. Peer Group Selection & Justification
B10: Criteria: (1) U.S. construction aggregates/materials as primary business, (2) Publicly traded with comparable financial disclosure, (3) Revenue >$2B to ensure scale comparability, (4) Aggregates or cement as core segment — excludes diversified industrials with minor materials exposure.
B12: Ticker | C12: Company | D12: Revenue ($mm) | E12: EBITDA Margin | F12: Selection Rationale | G12: Inclusion | H12: Adjustment
B13: VMC | C13: Vulcan Materials Co | D13: 7941.1 | E13: 0.29 | F13: Subject company; #2 U.S. crushed stone | G13: Subject | H13: —
B14: MLM | C14: Martin Marietta Materials | D14: 6150 | E14: 0.35 | F14: Closest comp; #1 crushed stone; duopoly with VMC | G14: Core Peer | H14: —
B15: CRH | C15: CRH plc | D15: 37447 | E15: 0.2 | F15: Global diversified; U.S. via Oldcastle; larger scale | G15: Core Peer | H15: Discount for non-U.S. mix
B16: CX | C16: CEMEX SAB de CV | D16: 16132 | E16: 0.14 | F16: Global cement/aggregates; Mexico-heavy | G16: Extended Peer | H16: Discount for EM risk
B17: EXP | C17: Eagle Materials Inc | D17: 2261 | E17: 0.34 | F17: Smaller; cement + gypsum; highest ROIC | G17: Extended Peer | H17: Premium for margin quality
B18: KNF | C18: Knife River Corp | D18: 3146 | E18: 0.16 | F18: Recently spun off; NW/Mountain; contracting mix | G18: Extended Peer | H18: Discount for limited history
B20: C. Current Peer Multiples (LTM)
B21: Ticker | C21: Mkt Cap ($mm) | D21: Net Debt ($mm) | E21: EV ($mm) | F21: Revenue ($mm) | G21: EBITDA ($mm) | H21: EV / EBITDA | I21: EV / Revenue | J21: Trailing P/E | K21: Forward P/E
B22: VMC | C22: 38649 | D22: 4190 | E22: =C22+D22 -> 42839 | F22: 7941 | G22: 2276 | H22: 18.8 | I22: 5.4 | J22: 31.71 | K22: 27.55
B23: MLM | C23: 39834 | D23: 5558 | E23: =C23+D23 -> 45392 | F23: 6150 | G23: 2130 | H23: 21.3 | I23: 7.4 | J23: 34.31 | K23: 27.17
B24: CRH | C24: 76145 | D24: 14091 | E24: =C24+D24 -> 90236 | F24: 37447 | G24: 7479 | H24: 12.1 | I24: 2.4 | J24: 18.23 | K24: 17.01
B25: CX | C25: 17323 | D25: 4804 | E25: =C25+D25 -> 22127 | F25: 16132 | G25: 2296 | H25: 9,6x | I25: 1.5 | J25: 37 | K25: 13.59
B26: EXP | C26: 6729 | D26: 1218 | E26: =C26+D26 -> 7947 | F26: 2261 | G26: 765 | H26: 10.4 | I26: 3.5 | J26: 13.08 | K26: 13.48
B27: KNF | C27: 4970 | D27: 1042 | E27: =C27+D27 -> 6012 | F27: 3146 | G27: 491 | H27: 12.2 | I27: 1.9 | J27: 29.31 | K27: 25.38
B29: Min | H29: =MIN(H22:H27) -> 10.4 | I29: =MIN(I22:I27) -> 1.5 | J29: =MIN(J22:J27) -> 13.08 | K29: =MIN(K22:K27) -> 13.48
B30: Max | H30: =MAX(H23:H27) -> 21.3 | I30: =MAX(I23:I27) -> 7.4 | J30: =MAX(J23:J27) -> 37 | K30: =MAX(K23:K27) -> 27.17
B31: Peer Mean (ex-VMC) | H31: =AVERAGE(H23:H27) -> 14 | I31: =AVERAGE(I23:I27) -> 3.34 | J31: =AVERAGE(J23:J27) -> 26.386 | K31: =AVERAGE(K23:K27) -> 19.326
B32: Peer Median (ex-VMC) | H32: =MEDIAN(H23:H27) -> 12.15 | I32: =MEDIAN(I23:I27) -> 2.4 | J32: =MEDIAN(J23:J27) -> 29.31 | K32: =MEDIAN(K23:K27) -> 17.01
B35: D. VMC Historical EV/EBITDA (FY2021–FY2025)
B36: Period | C36: Share Price ($) | D36: Shares (mm) | E36: Mkt Cap ($mm) | F36: Net Debt ($mm) | G36: EV ($mm) | H36: EBITDA ($mm) | I36: EV / EBITDA
B37: FY2025 | C37: 296 | D37: 131 | E37: 38649 | F37: ='9. Standardlized_Income'!D31-'9. Standardlized_Income'!D8 -> 4189.6 | G37: =E37+F37 -> 42838.6 | H37: ='2. Financial_Analyst'!G10 -> 2275.9 | I37: =G37/H37 -> 18.822708
B38: FY2024 | C38: 243.17 | D38: 132 | E38: =C38*D38 -> 32098.44 | F38: ='9. Standardlized_Income'!E31-'9. Standardlized_Income'!E8 -> 4768.1 | G38: =E38+F38 -> 36866.54 | H38: ='2. Financial_Analyst'!F10 -> 2028.3 | I38: =G38/H38 -> 18.176078
B39: FY2023 | C39: 223.99 | D39: 133 | E39: =C39*D39 -> 29790.67 | F39: ='9. Standardlized_Income'!F31-'9. Standardlized_Income'!F8 -> 2975.8 | G39: =E39+F39 -> 32766.47 | H39: ='2. Financial_Analyst'!E10 -> 1939.2 | I39: =G39/H39 -> 16.896901
B40: FY2022 | C40: 173.55 | D40: 133 | E40: =C40*D40 -> 23082.15 | F40: ='9. Standardlized_Income'!G31-'9. Standardlized_Income'!G8 -> 3871.4 | G40: =E40+F40 -> 26953.55 | H40: ='2. Financial_Analyst'!D10 -> 1617 | I40: =G40/H40 -> 16.668862
B41: FY2021 | C41: 204.79 | D41: 133 | E41: =C41*D41 -> 27237.07 | F41: ='9. Standardlized_Income'!H31-'9. Standardlized_Income'!H8 -> 3740.9 | G41: =E41+F41 -> 30977.97 | H41: ='2. Financial_Analyst'!C10 -> 1434.7 | I41: =G41/H41 -> 21.59195
B43: 5-year average | I43: =AVERAGE(I37:I41) -> 18.4313
B44: 5-year median | I44: =MEDIAN(I37:I41) -> 18.176078
B46: F. Target Price Derivation
B47: Key Assumptions | C47: Value | D47: Note
B48: Analysis Date | C48: 46115
...

Sheet 7. DDM_Valuation
B1: 7. Dividend Discount Model (DDM) — Vulcan Materials Company (VMC)
A3: A | B3: Model Objective & Methodology
B5: Model | C5: 3-Stage Dividend Discount Model
B6: Currency | C6: USD / share
B7: Valuation Date | C7: 46085
B8: Fiscal Year Basis | C8: December fiscal year-end (FY2021 – FY2025)
B9: Purpose | C9: DDM is used as a secondary equity valuation cross-check given VMC is not primarily valued on dividend yield. Vulcan retains ~75% of earnings for growth capex and acquisitions; the model therefore complements the DCF (FCFF/FCFE) and multiple-based approaches.
A12: B | B12: Historical Dividend & Payout Profile
B14: Table 1 — Dividend History & Payout Ratios
B15: ($mm unless noted) | C15: FY2021 | D15: FY2022 | E15: FY2023 | F15: FY2024 | G15: FY2025 | H15: 5Y Avg / CAGR
B16: DPS ($) | C16: =Sheet10!G320 -> 1.48 | D16: =Sheet10!F320 -> 1.6 | E16: =Sheet10!E320 -> 1.72 | F16: =Sheet10!D320 -> 1.84 | G16: =Sheet10!C320 -> 1.96 | H16: =(G16/C16)^(1/4)-1 -> 0.072750162
B17: DPS Growth (%) | C17: — | D17: =D16/C16-1 -> 0.081081081 | E17: =E16/D16-1 -> 0.075 | F17: =F16/E16-1 -> 0.069767442 | G17: =G16/F16-1 -> 0.065217391 | H17: =AVERAGE(D17:G17) -> 0.072766479
B18: EPS - Diluted ($) | C18: =Sheet10!G309 -> 5.05 | D18: =Sheet10!F309 -> 4.45 | E18: =Sheet10!E309 -> 7.06 | F18: =Sheet10!D309 -> 6.91 | G18: =Sheet10!C309 -> 8.15 | H18: =(G18/C18)^(1/4)-1 -> 0.12711066
B19: Net Income | C19: ='9. Standardlized_Income'!H44 -> 670.8 | D19: ='9. Standardlized_Income'!G44 -> 575.6 | E19: ='9. Standardlized_Income'!F44 -> 933.2 | F19: ='9. Standardlized_Income'!E44 -> 911.9 | G19: ='9. Standardlized_Income'!D44 -> 1076.7 | H19: =(G19/C19)^(1/4)-1 -> 0.12557753
B20: Dividends Paid | C20: ='9. Standardlized_Income'!H59 -> 196.4 | D20: ='9. Standardlized_Income'!G59 -> 212.6 | E20: ='9. Standardlized_Income'!F59 -> 228.4 | F20: ='9. Standardlized_Income'!E59 -> 244.4 | G20: ='9. Standardlized_Income'!D59 -> 259.8 | H20: =(G20/C20)^(1/4)-1 -> 0.072443486
B21: Dividend Payout Ratio (Div / NI) | C21: =C20/C19 -> 0.29278473 | D21: =D20/D19 -> 0.36935372 | E21: =E20/E19 -> 0.24474925 | F21: =F20/F19 -> 0.26801184 | G21: =G20/G19 -> 0.24129284 | H21: =AVERAGE(C21:G21) -> 0.28323848
B22: Retention Ratio (1 – Payout) | C22: =1-C21 -> 0.70721527 | D22: =1-D21 -> 0.63064628 | E22: =1-E21 -> 0.75525075 | F22: =1-F21 -> 0.73198816 | G22: =1-G21 -> 0.75870716 | H22: =AVERAGE(C22:G22) -> 0.71676152
B25: Table 2 — Cash Flow Coverage of Dividends
B26: ($mm unless noted) | C26: FY2021 | D26: FY2022 | E26: FY2023 | F26: FY2024 | G26: FY2025 | H26: 5Y Avg
B27: Net Cash from Operations | C27: ='9. Standardlized_Income'!H51 -> 1011.9 | D27: ='9. Standardlized_Income'!G51 -> 1148.2 | E27: ='9. Standardlized_Income'!F51 -> 1536.8 | F27: ='9. Standardlized_Income'!E51 -> 1409.6 | G27: ='9. Standardlized_Income'!D51 -> 1813 | H27: =AVERAGE(C27:G27) -> 1383.9
B28: Capital Expenditures | C28: ='9. Standardlized_Income'!H52 -> 451.3 | D28: ='9. Standardlized_Income'!G52 -> 612.6 | E28: ='9. Standardlized_Income'!F52 -> 872.6 | F28: ='9. Standardlized_Income'!E52 -> 603.5 | G28: ='9. Standardlized_Income'!D52 -> 677.7 | H28: =AVERAGE(C28:G28) -> 643.54
B29: Free Cash Flow (OCF – Capex) | C29: =C27-C28 -> 560.6 | D29: =D27-D28 -> 535.6 | E29: =E27-E28 -> 664.2 | F29: =F27-F28 -> 806.1 | G29: =G27-G28 -> 1135.3 | H29: =AVERAGE(C29:G29) -> 740.36
B30: Dividends Paid | C30: =C20 -> 196.4 | D30: =D20 -> 212.6 | E30: =E20 -> 228.4 | F30: =F20 -> 244.4 | G30: =G20 -> 259.8 | H30: =AVERAGE(C30:G30) -> 228.32
B31: FCF after Dividends | C31: =C29-C30 -> 364.2 | D31: =D29-D30 -> 323 | E31: =E29-E30 -> 435.8 | F31: =F29-F30 -> 561.7 | G31: =G29-G30 -> 875.5 | H31: =AVERAGE(C31:G31) -> 512.04
B33: Free Cash Flow to Equity (FCFE) | C33: =Sheet10!G436 -> 911.9 | D33: =Sheet10!F436 -> 632.8 | E33: =Sheet10!E436 -> 627.5 | F33: =Sheet10!D436 -> 2297.3 | G33: =Sheet10!C436 -> 198 | H33: =AVERAGE(C33:G33) -> 933.5
B35: Div / FCF | C35: =C30/C29 -> 0.35033892 | D35: =D30/D29 -> 0.39693801 | E35: =E30/E29 -> 0.34387233 | F35: =F30/F29 -> 0.30318819 | G35: =G30/G29 -> 0.22883819 | H35: =AVERAGE(C35:G35) -> 0.32463513
B36: Div / FCFE | C36: =IF(C33<=0,"n/m",C30/C33) -> 0.21537449 | D36: =IF(D33<=0,"n/m",D30/D33) -> 0.33596713 | E36: =IF(E33<=0,"n/m",E30/E33) -> 0.36398406 | F36: =IF(F33<=0,"n/m",F30/F33) -> 0.10638576 | G36: =IF(G33<=0,"n/m",G30/G33) -> 1.3121212 | H36: {=AVERAGE(IF(ISNUMBER(C36:G36),C36:G36))} -> 0.46676653
B37: FCF Dividend Coverage (x) | C37: =C29/C30 -> 2.8543788 | D37: =D29/D30 -> 2.519285 | E37: =E29/E30 -> 2.908056 | F37: =F29/F30 -> 3.2982815 | G37: =G29/G30 -> 4.3698999 | H37: =AVERAGE(C37:G37) -> 3.1899803
